Workbook

Sheet Instructions
B1: CASWJ Volunteer Hours Tracking
B3: Use this workbook to record volunteer service completed for CASWJ and its Artistic Organizations. Volunteer hours may be entered by individual volunteers or by an authorized coordinator on behalf of a group.
B5: Volunteer time is valued using either CASWJ's current Utah volunteer valuation rate or an approved professional billing rate, depending on the volunteer's assigned rate type.
B8: How to Enter Volunteer Hours
B10: 1. Go to the Volunteer Log sheet.
B11: 2. Enter the date the volunteer service occurred.
B12: 3. Select the Project / Event, Volunteer, Group / Organization, and Task Category.
B13: 4. Choose the Entry Method:
C14: • Start / End Time: enter the start and end times.
C15: • Total Hours: enter the total time in Manual Hours.
B16: 5. Review the calculated Hours, Hourly Rate, and In-Kind Value.
B17: 6. Select any applicable Tags and identify who entered the record.
B18: 7. Enter the Date Entered and add Notes when additional context is helpful.
B21: Volunteer Rates & In-Kind Value
B23: CASWJ uses a standard Utah volunteer valuation rate for most volunteer service. When a volunteer is providing professional services and has an approved professional billing rate, that rate may be used instead. The In-Kind Value is calculated automatically by multiplying the volunteer's recorded hours by the applicable hourly rate. Professional billing rates should only be used when they reasonably reflect the volunteer's normal rate for the professional service being provided.
B26: Workbook Guide
B28: Instructions Overview and instructions for using this workbook. Volunteer Log Enter and review individual volunteer service records. Volunteers Maintain the volunteer roster, contact information, status, and assigned rate type. Lists & Settings Maintain dropdown lists, organization names, task categories, projects/events, tags, and valuation settings. Summary Review volunteer hours, in-kind value, organization totals, task categories, monthly activity, top volunteers, and project/event totals.
B31: Data Entry Reminders
B33: • Enter volunteer service as soon as practical after it occurs.
B34: • Use the most accurate Entry Method available.
B35: • Do not enter the same volunteer service more than once.
B36: • Select the organization that received the benefit of the volunteer service.
... B44: For questions about volunteer hour reporting, rate types, projects/events, or corrections to submitted entries, contact the Cultural Arts Society of West Jordan. Do not change formulas, protected settings, or summary calculations unless you are authorized to maintain this workbook.

Sheet Volunteer Log
A1: Date | B1: Project / Event | C1: Volunteer | D1: Group / Organization | E1: Task Category | F1: Entry Method | G1: Start Time | H1: End Time | I1: Manual Duration | J1: Hours | K1: Rate Type | L1: Hourly Rate | M1: In-Kind Value | N1: Tags | O1: Entered By | P1: Date Entered | Q1: Hour Attribution | R1: Notes | S1: Volunteer ID
A2: 46053 | B2: General - West Jordan Symphony | C2: Trevor McFarland | D2: West Jordan Symphony | E2: Committee Member Hours | F2: Total Hours | G2: 0.875 | H2: 0.91666667 | I2: 1.0416667 | J2: {=IF(A2:A992="","", IF(F2:F992="Total Hours", IF(I2:I992="","",I2:I992*24), IF(F2:F992="Start / End Time", IF((G2:G992="")+(H2:H992=""),"",24*MOD(H2:H992-G2:G992,1)), "" ) ) )} -> 25 | K2: {=MAP(C2:C991,LAMBDA(name, IF(name="","", IFERROR( _xlfn.XLOOKUP( TRIM(CLEAN(name)), TRIM(CLEAN(Volunteers!D2:D999)), Volunteers!I2:I999 ), "" ))))} -> Utah Volunteer Rate | L2: {=IF(C2:C991="","", IFNA(VLOOKUP(C2:C991,Volunteers!D:K,8,FALSE),"") )} -> 35.47 | M2: {=IF((J2:J991="")+(L2:L991=""),"", J2:J991*L2:L991 )} -> 886.75 | N2: (Org) West Jordan Symphony, (Type) Committee Member Hours | O2: Clockify Import | P2: 46053 | R2: Trevor McFarland - Director/January | T2: {=IF(I2:I238="","",I2:I238/24)} -> 0.043402778
A3: 46053 | B3: General - West Jordan Symphony | C3: Samuel Abramson | D3: West Jordan Symphony | E3: Committee Member Hours | F3: Total Hours | G3: 0.875 | H3: 0.91666667 | I3: 1.0416667 | J3: 25 | K3: Utah Volunteer Rate | L3: 35.47 | M3: 886.75 | N3: (Org) West Jordan Symphony, (Type) Committee Member Hours | O3: Clockify Import | P3: 46053 | R3: Sam Abramson- Assistant Director/January | T3: 0.043402778
A4: 46053 | B4: General - West Jordan Youth Theatre | C4: Alex Moffitt | D4: West Jordan Youth Theatre | E4: Participant Hours | F4: Total Hours | G4: 0.75902778 | H4: 0.17569444 | I4: 30.416667 | J4: 730 | K4: Utah Volunteer Rate | L4: 35.47 | M4: 25893.1 | N4: (Org) West Jordan Youth Theatre | O4: Clockify Import | P4: 46053 | R4: WJYT January Volunteer Hours | S4: {=IF(C4="","",IFERROR(_xlfn.XLOOKUP(C4,Volunteers!D:D,Volunteers!A:A),""))} -> 001 | T4: 1.2673611
A5: 46053 | B5: General - West Jordan Symphony | C5: Diana Larsen | D5: West Jordan Symphony | E5: Committee Member Hours | F5: Total Hours | G5: 0.375 | H5: 0.41666667 | I5: 1.0416667 | J5: 25 | K5: Utah Volunteer Rate | L5: 35.47 | M5: 886.75 | N5: (Org) West Jordan Symphony, (Type) Committee Member Hours | O5: Clockify Import | P5: 46053 | R5: Board members/January | S5: {=IF(C5="","",IFERROR(_xlfn.XLOOKUP(C5,Volunteers!D:D,Volunteers!A:A),""))} -> 007 | T5: 0.043402778
A6: 46053 | B6: General - West Jordan Symphony | C6: Diana Larsen | D6: West Jordan Symphony | E6: Participant Hours | F6: Total Hours | G6: 0.375 | H6: 0.85416667 | I6: 4.4791667 | J6: 107.5 | K6: Utah Volunteer Rate | L6: 35.47 | M6: 3813.025 | N6: (Type) Participant Hours, (Org) West Jordan Symphony | O6: Clockify Import | P6: 46053 | R6: Rehearsal | S6: {=IF(C6="","",IFERROR(_xlfn.XLOOKUP(C6,Volunteers!D:D,Volunteers!A:A),""))} -> 007 | T6: 0.18663194
A7: 46050 | B7: Art in the Park 2026 | C7: Briana Thaxton | D7: Visual Arts Society | E7: Committee Member Hours | F7: Total Hours | G7: 0.54166667 | H7: 0.58680556 | I7: 0.045138875 | J7: 1.083333 | K7: Utah Volunteer Rate | L7: 35.47 | M7: 38.425822 | N7: (Event) Art in the Park 2026, (Org) Visual Arts Society, (Type) Committee Member Hours | O7: Clockify Import | P7: 46050 | R7: Google Meet with Dillon | S7: {=IF(C7="","",IFERROR(_xlfn.XLOOKUP(C7,Volunteers!D:D,Volunteers!A:A),""))} -> 003 | T7: 0.0018807865
A8: 46046 | B8: General - West Jordan Symphony | C8: Diana Larsen | D8: West Jordan Symphony | E8: Participant Hours | F8: Total Hours | G8: 0.375 | H8: 0.375 | I8: 5 | J8: 120 | K8: Utah Volunteer Rate | L8: 35.47 | M8: 4256.4 | N8: (Type) Participant Hours, (Org) West Jordan Symphony | O8: Clockify Import | P8: 46046 | R8: Rehearsal | S8: {=IF(C8="","",IFERROR(_xlfn.XLOOKUP(C8,Volunteers!D:D,Volunteers!A:A),""))} -> 007 | T8: 0.20833333
A9: 46043 | B9: Art in the Park 2026 | C9: Briana Thaxton | D9: Visual Arts Society | E9: Committee Member Hours | F9: Total Hours | G9: 0.54166667 | H9: 0.63888889 | I9: 0.097222208 | J9: 2.333333 | K9: Utah Volunteer Rate | L9: 35.47 | M9: 82.763322 | N9: (Event) Art in the Park 2026, (Type) Committee Member Hours, (Org) Visual Arts Society | O9: Clockify Import | P9: 46043 | R9: Google Meet with Dillon | S9: {=IF(C9="","",IFERROR(_xlfn.XLOOKUP(C9,Volunteers!D:D,Volunteers!A:A),""))} -> 003 | T9: 0.0040509253
A10: 46039 | B10: General - West Jordan Symphony | C10: Diana Larsen | D10: West Jordan Symphony | E10: Participant Hours | F10: Total Hours | G10: 0.375 | H10: 0.54166667 | I10: 4.1666667 | J10: 100 | K10: Utah Volunteer Rate | L10: 35.47 | M10: 3547 | N10: (Type) Participant Hours, (Org) West Jordan Symphony | O10: Clockify Import | P10: 46039 | R10: Rehearsal | S10: {=IF(C10="","",IFERROR(_xlfn.XLOOKUP(C10,Volunteers!D:D,Volunteers!A:A),""))} -> 007 | T10: 0.17361111
A11: 46032 | B11: General - West Jordan Symphony | C11: Diana Larsen | D11: West Jordan Symphony | E11: Participant Hours | F11: Total Hours | G11: 0.375 | H11: 0.64583333 | I11: 4.2708333 | J11: 102.5 | K11: Utah Volunteer Rate | L11: 35.47 | M11: 3635.675 | N11: (Type) Participant Hours, (Org) West Jordan Symphony | O11: Clockify Import | P11: 46032 | R11: Rehearsal | S11: {=IF(C11="","",IFERROR(_xlfn.XLOOKUP(C11,Volunteers!D:D,Volunteers!A:A),""))} -> 007 | T11: 0.17795139
A12: 46081 | B12: General - West Jordan Symphony | D12: West Jordan Symphony | E12: Committee Member Hours | F12: Total Hours | G12: 0.91666667 | H12: 0.95833333 | I12: 1.0416667 | J12: 25 | N12: (Org) West Jordan Symphony, (Type) Committee Member Hours | O12: Clockify Import | P12: 46081 | R12: Board members/January | S12: {=IF(C12="","",IFERROR(_xlfn.XLOOKUP(C12,Volunteers!D:D,Volunteers!A:A),""))} | T12: 0.043402778
A13: 46081 | B13: General - West Jordan Symphony | C13: Samuel Abramson | D13: West Jordan Symphony | E13: Committee Member Hours | F13: Total Hours | G13: 0.875 | H13: 0.91666667 | I13: 1.0416667 | J13: 25 | K13: Utah Volunteer Rate | L13: 35.47 | M13: 886.75 | N13: (Org) West Jordan Symphony, (Type) Committee Member Hours | O13: Clockify Import | P13: 46081 | R13: Sam Abramson- Assistant Director/February | S13: {=IF(C13="","",IFERROR(_xlfn.XLOOKUP(C13,Volunteers!D:D,Volunteers!A:A),""))} -> 015 | T13: 0.043402778
A14: 46081 | B14: General - West Jordan Symphony | C14: Trevor McFarland | D14: West Jordan Symphony | E14: Committee Member Hours | F14: Total Hours | G14: 0.875 | H14: 0.91666667 | I14: 1.0416667 | J14: 25 | K14: Utah Volunteer Rate | L14: 35.47 | M14: 886.75 | N14: (Org) West Jordan Symphony, (Type) Committee Member Hours | O14: Clockify Import | P14: 46081 | R14: Trevor McFarland - Director/February | S14: {=IF(C14="","",IFERROR(_xlfn.XLOOKUP(C14,Volunteers!D:D,Volunteers!A:A),""))} -> 016 | T14: 0.043402778
A15: 46081 | B15: General - West Jordan Youth Theatre | C15: Alex Moffitt | D15: West Jordan Youth Theatre | E15: Participant Hours | F15: Total Hours | G15: 0.84236111 | H15: 0.0090277778 | I15: 2.1666667 | J15: 52 | K15: Utah Volunteer Rate | L15: 35.47 | M15: 1844.44 | N15: (Org) West Jordan Youth Theatre, (Type) Participant Hours | O15: Clockify Import | P15: 46081 | R15: WJYT February Volunteer hours | S15: {=IF(C15="","",IFERROR(_xlfn.XLOOKUP(C15,Volunteers!D:D,Volunteers!A:A),""))} -> 001 | T15: 0.090277778
A16: 46081 | B16: General - West Jordan Symphony | C16: Diana Larsen | D16: West Jordan Symphony | E16: Participant Hours | F16: Total Hours | G16: 0.75 | H16: 0.4375 | I16: 4.6875 | J16: 112.5 | K16: Utah Volunteer Rate | L16: 35.47 | M16: 3990.375 | N16: (Type) Participant Hours, (Org) West Jordan Symphony | O16: Clockify Import | P16: 46081 | R16: Concert | S16: {=IF(C16="","",IFERROR(_xlfn.XLOOKUP(C16,Volunteers!D:D,Volunteers!A:A),""))} -> 007 | T16: 0.1953125
A17: 46081 | B17: General - Visual Arts Society | C17: Anna Nelson | D17: Visual Arts Society | E17: Committee Member Hours | F17: Total Hours | G17: 0.58680556 | H17: 0.65625 | I17: 0.069444458 | J17: 1.666667 | K17: Utah Volunteer Rate | L17: 35.47 | M17: 59.116678 | N17: (Type) Committee Member Hours | O17: Clockify Import | P17: 46081 | R17: WJAC Meeting | S17: {=IF(C17="","",IFERROR(_xlfn.XLOOKUP(C17,Volunteers!D:D,Volunteers!A:A),""))} -> 002 | T17: 0.0028935191
A18: 46081 | B18: General - Visual Arts Society | C18: Maya Collinwood | D18: Visual Arts Society | E18: Committee Member Hours | F18: Total Hours | G18: 0.58333333 | H18: 0.66666667 | I18: 0.083333333 | J18: 2 | K18: Utah Volunteer Rate | L18: 35.47 | M18: 70.94 | N18: (Type) Committee Member Hours | O18: Clockify Import | P18: 46081 | R18: Committee meeting | S18: {=IF(C18="","",IFERROR(_xlfn.XLOOKUP(C18,Volunteers!D:D,Volunteers!A:A),""))} -> 013 | T18: 0.0034722222
A19: 46081 | B19: Art in the Park May 2026 | C19: Briana Thaxton | D19: Visual Arts Society | E19: Committee Member Hours | F19: Total Hours | G19: 0.58333333 | H19: 0.65625 | I19: 0.072916667 | J19: 1.75 | K19: Utah Volunteer Rate | L19: 35.47 | M19: 62.0725 | N19: (Event) Art in the Park 2026, (Org) Visual Arts Society, (Type) Committee Member Hours | O19: Clockify Import | P19: 46081 | R19: Meeting with Michael | S19: {=IF(C19="","",IFERROR(_xlfn.XLOOKUP(C19,Volunteers!D:D,Volunteers!A:A),""))} -> 003 | T19: 0.0030381944
A20: 46081 | B20: General - Literary Arts Society | C20: Rachel O'Crowley | D20: CASWJ | E20: CASWJ Board Hours | F20: Total Hours | G20: 0.375 | H20: 0.70833333 | I20: 0.33333333 | J20: 8 | K20: Utah Volunteer Rate | L20: 35.47 | M20: 283.76 | N20: (Type) CASWJ Board Hours | O20: Clockify Import | P20: 46081 | R20: CASWJ Board Hours | S20: {=IF(C20="","",IFERROR(_xlfn.XLOOKUP(C20,Volunteers!D:D,Volunteers!A:A),""))} -> 014 | T20: 0.013888889
A21: 46081 | B21: General - Visual Arts Society | C21: Rachel O'Crowley | D21: Visual Arts Society | E21: Committee Member Hours | F21: Total Hours | G21: 0.375 | H21: 0.79166667 | I21: 0.41666667 | J21: 10 | K21: Utah Volunteer Rate | L21: 35.47 | M21: 354.7 | N21: (Type) Committee Member Hours | O21: Clockify Import | P21: 46081 | R21: Visual Arts | S21: {=IF(C21="","",IFERROR(_xlfn.XLOOKUP(C21,Volunteers!D:D,Volunteers!A:A),""))} -> 014 | T21: 0.017361111
A22: 46081 | B22: General - West Jordan Symphony | C22: Diana Larsen | D22: West Jordan Symphony | E22: Participant Hours | F22: Total Hours | G22: 0.375 | H22: 0.16666667 | I22: 4.7916667 | J22: 115 | K22: Utah Volunteer Rate | L22: 35.47 | M22: 4079.05 | N22: (Type) Participant Hours, (Org) West Jordan Symphony | O22: Clockify Import | P22: 46081 | R22: Rehearsal | S22: {=IF(C22="","",IFERROR(_xlfn.XLOOKUP(C22,Volunteers!D:D,Volunteers!A:A),""))} -> 007 | T22: 0.19965278
A23: 46081 | C23: Lynette Owens | E23: CASWJ Board Hours | F23: Total Hours | G23: 0.36458333 | H23: 0.42083333 | I23: 0.05625 | J23: 1.35 | K23: Utah Volunteer Rate | L23: 35.47 | M23: 47.8845 | N23: (Type) CASWJ Board Hours | O23: Clockify Import | P23: 46081 | R23: CASWJ entities review | S23: {=IF(C23="","",IFERROR(_xlfn.XLOOKUP(C23,Volunteers!D:D,Volunteers!A:A),""))} -> 011 | T23: 0.00234375
A24: 46081 | B24: General / No Specific Project | C24: Chelsea McGee | D24: CASWJ | E24: CASWJ Board Hours | F24: Total Hours | G24: 0.29791667 | H24: 0.96458333 | I24: 0.66666667 | J24: 16 | K24: Utah Volunteer Rate | L24: 35.47 | M24: 567.52 | N24: (Org) CASWJ Board, (Type) CASWJ Board Hours | O24: Clockify Import | P24: 46081 | R24: Treasurer tasks February | S24: {=IF(C24="","",IFERROR(_xlfn.XLOOKUP(C24,Volunteers!D:D,Volunteers!A:A),""))} -> 005 | T24: 0.027777778
A25: 46081 | B25: General - West Jordan Youth Theatre | C25: Alex Moffitt | D25: West Jordan Youth Theatre | E25: Participant Hours | F25: Total Hours | G25: 0.17569444 | H25: 0.84236111 | I25: 41.625 | J25: 999 | K25: Utah Volunteer Rate | L25: 35.47 | M25: 35434.53 | N25: (Org) West Jordan Youth Theatre | O25: Clockify Import | P25: 46081 | R25: WJYT February Volunteer hours | S25: {=IF(C25="","",IFERROR(_xlfn.XLOOKUP(C25,Volunteers!D:D,Volunteers!A:A),""))} -> 001 | T25: 1.734375
A26: 46079 | C26: Lynette Owens | E26: CASWJ Board Hours | F26: Total Hours | G26: 0.40625 | H26: 0.43402778 | I26: 0.027777792 | J26: 0.666667 | K26: Utah Volunteer Rate | L26: 35.47 | M26: 23.646678 | N26: (Type) CASWJ Board Hours | O26: Clockify Import | P26: 46079 | R26: CASWJ entities review | S26: {=IF(C26="","",IFERROR(_xlfn.XLOOKUP(C26,Volunteers!D:D,Volunteers!A:A),""))} -> 011 | T26: 0.001157408
A27: 46078 | B27: Art in the Park May 2026 | C27: Briana Thaxton | D27: Visual Arts Society | E27: Committee Member Hours | F27: Total Hours | G27: 0.49027778 | H27: 0.51041667 | I27: 0.020138875 | J27: 0.483333 | K27: Utah Volunteer Rate | L27: 35.47 | M27: 17.143822 | N27: (Event) Art in the Park 2026, (Org) Visual Arts Society, (Type) Committee Member Hours | O27: Clockify Import | P27: 46078 | R27: Artist Apps | S27: {=IF(C27="","",IFERROR(_xlfn.XLOOKUP(C27,Volunteers!D:D,Volunteers!A:A),""))} -> 003 | T27: 0.00083911979
A28: 46077 | C28: Lynette Owens | E28: CASWJ Board Hours | F28: Total Hours | G28: 0.37847222 | H28: 0.40625 | I28: 0.027777792 | J28: 0.666667 | K28: Utah Volunteer Rate | L28: 35.47 | M28: 23.646678 | N28: (Type) CASWJ Board Hours | O28: Clockify Import | P28: 46077 | R28: CASWJ entities review | S28: {=IF(C28="","",IFERROR(_xlfn.XLOOKUP(C28,Volunteers!D:D,Volunteers!A:A),""))} -> 011 | T28: 0.001157408
A29: 46074 | C29: Lynette Owens | E29: CASWJ Board Hours | F29: Total Hours | G29: 0.55208333 | H29: 0.60416667 | I29: 0.052083333 | J29: 1.25 | K29: Utah Volunteer Rate | L29: 35.47 | M29: 44.3375 | N29: (Type) CASWJ Board Hours | O29: Clockify Import | P29: 46074 | R29: (Without Description) | S29: {=IF(C29="","",IFERROR(_xlfn.XLOOKUP(C29,Volunteers!D:D,Volunteers!A:A),""))} -> 011 | T29: 0.0021701389
A30: 46074 | C30: Lynette Owens | E30: CASWJ Board Hours | F30: Total Hours | G30: 0.5 | H30: 0.55208333 | I30: 0.052083333 | J30: 1.25 | K30: Utah Volunteer Rate | L30: 35.47 | M30: 44.3375 | N30: (Type) CASWJ Board Hours | O30: Clockify Import | P30: 46074 | R30: CASWJ Board mtg | S30: {=IF(C30="","",IFERROR(_xlfn.XLOOKUP(C30,Volunteers!D:D,Volunteers!A:A),""))} -> 011 | T30: 0.0021701389
A31: 46074 | B31: General - West Jordan Symphony | C31: Diana Larsen | D31: West Jordan Symphony | E31: Participant Hours | F31: Total Hours | G31: 0.375 | H31: 0.0625 | I31: 4.6875 | J31: 112.5 | K31: Utah Volunteer Rate | L31: 35.47 | M31: 3990.375 | N31: (Type) Participant Hours, (Org) West Jordan Symphony | O31: Clockify Import | P31: 46074 | R31: Rehearsal | S31: {=IF(C31="","",IFERROR(_xlfn.XLOOKUP(C31,Volunteers!D:D,Volunteers!A:A),""))} -> 007 | T31: 0.1953125
A32: 46071 | B32: Art in the Park May 2026 | C32: Briana Thaxton | D32: Visual Arts Society | E32: Committee Member Hours | F32: Total Hours | G32: 0.39583333 | H32: 0.41736111 | I32: 0.021527792 | J32: 0.516667 | K32: Utah Volunteer Rate | L32: 35.47 | M32: 18.326178 | N32: (Event) Art in the Park 2026, (Org) Visual Arts Society, (Type) Committee Member Hours | O32: Clockify Import | P32: 46071 | R32: Artist Apps | S32: {=IF(C32="","",IFERROR(_xlfn.XLOOKUP(C32,Volunteers!D:D,Volunteers!A:A),""))} -> 003 | T32: 0.00089699132
A33: 46067 | B33: General - West Jordan Symphony | C33: Diana Larsen | D33: West Jordan Symphony | E33: Participant Hours | F33: Total Hours | G33: 0.375 | H33: 0.47916667 | I33: 5.1041667 | J33: 122.5 | K33: Utah Volunteer Rate | L33: 35.47 | M33: 4345.075 | N33: (Type) Participant Hours, (Org) West Jordan Symphony | O33: Clockify Import | P33: 46067 | R33: Rehearsal | S33: {=IF(C33="","",IFERROR(_xlfn.XLOOKUP(C33,Volunteers!D:D,Volunteers!A:A),""))} -> 007 | T33: 0.21267361
A34: 46066 | B34: General - West Jordan Youth Theatre | C34: Brook Mann | D34: West Jordan Youth Theatre | E34: Committee Member Hours | F34: Total Hours | G34: 0.80347222 | H34: 0.85902778 | I34: 0.055555542 | J34: 1.333333 | K34: Utah Volunteer Rate | L34: 35.47 | M34: 47.293322 | N34: (Org) West Jordan Youth Theatre, (Type) Committee Member Hours | O34: Clockify Import | P34: 46066 | R34: Ticket taking | S34: {=IF(C34="","",IFERROR(_xlfn.XLOOKUP(C34,Volunteers!D:D,Volunteers!A:A),""))} -> 004 | T34: 0.0023148142
A35: 46064 | B35: Art in the Park May 2026 | C35: Briana Thaxton | D35: Visual Arts Society | E35: Committee Member Hours | F35: Total Hours | G35: 0.90277778 | H35: 0.92083333 | I35: 0.018055542 | J35: 0.433333 | K35: Utah Volunteer Rate | L35: 35.47 | M35: 15.370322 | N35: (Event) Art in the Park 2026, (Org) Visual Arts Society, (Type) Committee Member Hours | O35: Clockify Import | P35: 46064 | R35: Artist Apps | S35: {=IF(C35="","",IFERROR(_xlfn.XLOOKUP(C35,Volunteers!D:D,Volunteers!A:A),""))} -> 003 | T35: 0.00075231424
A36: 46064 | B36: General - West Jordan Symphony | C36: Marche Weffer | D36: West Jordan Symphony | E36: Committee Member Hours | F36: Total Hours | G36: 0.46111111 | H36: 0.46875 | I36: 0.007638875 | J36: 0.183333 | K36: Utah Volunteer Rate | L36: 35.47 | M36: 6.5028215 | N36: (Type) Committee Member Hours | O36: Clockify Import | P36: 46064 | R36: Reviewing Annual Report | S36: {=IF(C36="","",IFERROR(_xlfn.XLOOKUP(C36,Volunteers!D:D,Volunteers!A:A),""))} -> 012 | T36: 0.00031828646
A37: 46064 | B37: General - West Jordan Symphony | C37: Marche Weffer | D37: West Jordan Symphony | E37: Committee Member Hours | F37: Total Hours | G37: 0.44305556 | H37: 0.45416667 | I37: 0.011111125 | J37: 0.266667 | K37: Utah Volunteer Rate | L37: 35.47 | M37: 9.4586785 | N37: (Type) Committee Member Hours | O37: Clockify Import | P37: 46064 | R37: Reviewing Annual Report | S37: {=IF(C37="","",IFERROR(_xlfn.XLOOKUP(C37,Volunteers!D:D,Volunteers!A:A),""))} -> 012 | T37: 0.00046296354
A38: 46064 | B38: General - West Jordan Symphony | C38: Marche Weffer | D38: West Jordan Symphony | E38: Committee Member Hours | F38: Total Hours | G38: 0.43680556 | H38: 0.44097222 | I38: 0.0041666667 | J38: 0.1 | K38: Utah Volunteer Rate | L38: 35.47 | M38: 3.547 | N38: (Type) Committee Member Hours | O38: Clockify Import | P38: 46064 | R38: Docusigning Code of Ethics | S38: {=IF(C38="","",IFERROR(_xlfn.XLOOKUP(C38,Volunteers!D:D,Volunteers!A:A),""))} -> 012 | T38: 0.00017361111
A39: 46064 | B39: General - West Jordan Symphony | C39: Marche Weffer | D39: West Jordan Symphony | E39: Committee Member Hours | F39: Total Hours | G39: 0.43194444 | H39: 0.43611111 | I39: 0.0041666667 | J39: 0.1 | K39: Utah Volunteer Rate | L39: 35.47 | M39: 3.547 | N39: (Org) West Jordan Symphony, (Type) Committee Member Hours | O39: Clockify Import | P39: 46064 | R39: Responding to request to join submissions | S39: {=IF(C39="","",IFERROR(_xlfn.XLOOKUP(C39,Volunteers!D:D,Volunteers!A:A),""))} -> 012 | T39: 0.00017361111
A40: 46063 | B40: General - West Jordan Symphony | C40: Kirstin Hoyt | D40: West Jordan Symphony | E40: Volunteer Hours | F40: Total Hours | G40: 0.75 | H40: 0.80208333 | I40: 0.052083333 | J40: 1.25 | K40: Utah Volunteer Rate | L40: 35.47 | M40: 44.3375 | N40: (Org) West Jordan Symphony, (Type) Volunteer Hours | O40: Clockify Import | P40: 46063 | R40: Sky Island Quartet Tickets | S40: {=IF(C40="","",IFERROR(_xlfn.XLOOKUP(C40,Volunteers!D:D,Volunteers!A:A),""))} -> 010 | T40: 0.0021701389
...

Sheet Volunteers
A1: Volunteer ID | B1: First Name | C1: Last Name | D1: Display Name | E1: Email | F1: Zip Code | G1: Primary Group | H1: Active? | I1: Rate Type | J1: Professional Billing Rate | K1: Effective Hourly Rate | L1: Notes
A2: =IF(B2="","",TEXT(ROW()-1,"000")) -> 001 | B2: Alex | C2: Moffitt | D2: =IF(OR(B2="",C2=""),"",B2&" "&C2) -> Alex Moffitt | G2: West Jordan Youth Theatre | H2: Yes | I2: Utah Volunteer Rate | K2: =IF(I2="Professional Billing Rate",J2,'Lists & Settings'!$E$2) -> 35.47
A3: =IF(B3="","",TEXT(ROW()-1,"000")) -> 002 | B3: Anna | C3: Nelson | D3: =IF(OR(B3="",C3=""),"",B3&" "&C3) -> Anna Nelson | G3: Visual Arts Society | H3: Yes | I3: Utah Volunteer Rate | K3: =IF(I3="Professional Billing Rate",J3,'Lists & Settings'!$E$2) -> 35.47
A4: =IF(B4="","",TEXT(ROW()-1,"000")) -> 003 | B4: Briana | C4: Thaxton | D4: =IF(OR(B4="",C4=""),"",B4&" "&C4) -> Briana Thaxton | G4: Visual Arts Society | H4: No | I4: Utah Volunteer Rate | K4: =IF(I4="Professional Billing Rate",J4,'Lists & Settings'!$E$2) -> 35.47
A5: =IF(B5="","",TEXT(ROW()-1,"000")) -> 004 | B5: Brook | C5: Mann | D5: =IF(OR(B5="",C5=""),"",B5&" "&C5) -> Brook Mann | G5: West Jordan Youth Theatre | H5: Yes | I5: Utah Volunteer Rate | K5: =IF(I5="Professional Billing Rate",J5,'Lists & Settings'!$E$2) -> 35.47
A6: =IF(B6="","",TEXT(ROW()-1,"000")) -> 005 | B6: Chelsea | C6: McGee | D6: =IF(OR(B6="",C6=""),"",B6&" "&C6) -> Chelsea McGee | G6: CASWJ | H6: Yes | I6: Utah Volunteer Rate | K6: =IF(I6="Professional Billing Rate",J6,'Lists & Settings'!$E$2) -> 35.47
A7: =IF(B7="","",TEXT(ROW()-1,"000")) -> 006 | B7: Clockify | C7: Import | D7: =IF(OR(B7="",C7=""),"",B7&" "&C7) -> Clockify Import | G7: CASWJ | H7: No | I7: Utah Volunteer Rate | K7: =IF(I7="Professional Billing Rate",J7,'Lists & Settings'!$E$2) -> 35.47
A8: =IF(B8="","",TEXT(ROW()-1,"000")) -> 007 | B8: Diana | C8: Larsen | D8: =IF(OR(B8="",C8=""),"",B8&" "&C8) -> Diana Larsen | G8: West Jordan Symphony | H8: Yes | I8: Utah Volunteer Rate | K8: =IF(I8="Professional Billing Rate",J8,'Lists & Settings'!$E$2) -> 35.47
A9: =IF(B9="","",TEXT(ROW()-1,"000")) -> 008 | B9: Janessa | C9: Kimball | D9: =IF(OR(B9="",C9=""),"",B9&" "&C9) -> Janessa Kimball | G9: CASWJ | H9: Yes | I9: Utah Volunteer Rate | K9: =IF(I9="Professional Billing Rate",J9,'Lists & Settings'!$E$2) -> 35.47
A10: =IF(B10="","",TEXT(ROW()-1,"000")) -> 009 | B10: Jen | C10: Crabb | D10: =IF(OR(B10="",C10=""),"",B10&" "&C10) -> Jen Crabb | G10: Sugar Factory Playhouse | H10: Yes | I10: Utah Volunteer Rate | K10: =IF(I10="Professional Billing Rate",J10,'Lists & Settings'!$E$2) -> 35.47
A11: =IF(B11="","",TEXT(ROW()-1,"000")) -> 010 | B11: Kirstin | C11: Hoyt | D11: =IF(OR(B11="",C11=""),"",B11&" "&C11) -> Kirstin Hoyt | G11: West Jordan Symphony | H11: Yes | I11: Utah Volunteer Rate | K11: =IF(I11="Professional Billing Rate",J11,'Lists & Settings'!$E$2) -> 35.47
A12: =IF(B12="","",TEXT(ROW()-1,"000")) -> 011 | B12: Lynette | C12: Owens | D12: =IF(OR(B12="",C12=""),"",B12&" "&C12) -> Lynette Owens | G12: CASWJ | H12: Yes | I12: Utah Volunteer Rate | K12: =IF(I12="Professional Billing Rate",J12,'Lists & Settings'!$E$2) -> 35.47
A13: =IF(B13="","",TEXT(ROW()-1,"000")) -> 012 | B13: Marche | C13: Weffer | D13: =IF(OR(B13="",C13=""),"",B13&" "&C13) -> Marche Weffer | G13: West Jordan Symphony | H13: Yes | I13: Utah Volunteer Rate | K13: =IF(I13="Professional Billing Rate",J13,'Lists & Settings'!$E$2) -> 35.47
... A17: =IF(B17="","",TEXT(ROW()-1,"000")) -> 016 | B17: Trevor | C17: McFarland | D17: =IF(OR(B17="",C17=""),"",B17&" "&C17) -> Trevor McFarland | G17: West Jordan Symphony | H17: Yes | I17: Utah Volunteer Rate | K17: =IF(I17="Professional Billing Rate",J17,'Lists & Settings'!$E$2) -> 35.47
A18: =IF(B18="","",TEXT(ROW()-1,"000")) -> 017 | B18: Michael | C18: Goodman | D18: =IF(OR(B18="",C18=""),"",B18&" "&C18) -> Michael Goodman | H18: Yes | I18: Utah Volunteer Rate | K18: =IF(I18="Professional Billing Rate",J18,'Lists & Settings'!$E$2) -> 35.47
A19: =IF(B19="","",TEXT(ROW()-1,"000")) | D19: =IF(OR(B19="",C19=""),"",B19&" "&C19) | K19: =IF(I19="Professional Billing Rate",J19,'Lists & Settings'!$E$2) -> 35.47
A20: =IF(B20="","",TEXT(ROW()-1,"000")) | D20: =IF(OR(B20="",C20=""),"",B20&" "&C20) | K20: =IF(I20="Professional Billing Rate",J20,'Lists & Settings'!$E$2) -> 35.47
A21: =IF(B21="","",TEXT(ROW()-1,"000")) | D21: =IF(OR(B21="",C21=""),"",B21&" "&C21) | K21: =IF(I21="Professional Billing Rate",J21,'Lists & Settings'!$E$2) -> 35.47
A22: =IF(B22="","",TEXT(ROW()-1,"000")) | D22: =IF(OR(B22="",C22=""),"",B22&" "&C22) | K22: =IF(I22="Professional Billing Rate",J22,'Lists & Settings'!$E$2) -> 35.47
A23: =IF(B23="","",TEXT(ROW()-1,"000")) | D23: =IF(OR(B23="",C23=""),"",B23&" "&C23) | K23: =IF(I23="Professional Billing Rate",J23,'Lists & Settings'!$E$2) -> 35.47
A24: =IF(B24="","",TEXT(ROW()-1,"000")) | D24: =IF(OR(B24="",C24=""),"",B24&" "&C24) | K24: =IF(I24="Professional Billing Rate",J24,'Lists & Settings'!$E$2) -> 35.47
A25: =IF(B25="","",TEXT(ROW()-1,"000")) | D25: =IF(OR(B25="",C25=""),"",B25&" "&C25) | K25: =IF(I25="Professional Billing Rate",J25,'Lists & Settings'!$E$2) -> 35.47
A26: =IF(B26="","",TEXT(ROW()-1,"000")) | D26: =IF(OR(B26="",C26=""),"",B26&" "&C26) | K26: =IF(I26="Professional Billing Rate",J26,'Lists & Settings'!$E$2) -> 35.47
A27: =IF(B27="","",TEXT(ROW()-1,"000")) | D27: =IF(OR(B27="",C27=""),"",B27&" "&C27) | K27: =IF(I27="Professional Billing Rate",J27,'Lists & Settings'!$E$2) -> 35.47
A28: =IF(B28="","",TEXT(ROW()-1,"000")) | D28: =IF(OR(B28="",C28=""),"",B28&" "&C28) | K28: =IF(I28="Professional Billing Rate",J28,'Lists & Settings'!$E$2) -> 35.47
A29: =IF(B29="","",TEXT(ROW()-1,"000")) | D29: =IF(OR(B29="",C29=""),"",B29&" "&C29) | K29: =IF(I29="Professional Billing Rate",J29,'Lists & Settings'!$E$2) -> 35.47
A30: =IF(B30="","",TEXT(ROW()-1,"000")) | D30: =IF(OR(B30="",C30=""),"",B30&" "&C30) | K30: =IF(I30="Professional Billing Rate",J30,'Lists & Settings'!$E$2) -> 35.47
... A999: =IF(B999="","",TEXT(ROW()-1,"000")) | D999: =IF(OR(B999="",C999=""),"",B999&" "&C999) | K999: =IF(I999="Professional Billing Rate",J999,'Lists & Settings'!$E$2) -> 35.47

Sheet Lists & Settings
A1: Setting | G1: Rate Types | J1: Task Categories | M1: Groups / Organizations | P1: Entry Methods | R1: Tags
A2: Current Utah Volunteer Rate | E2: 35.47 | G2: Utah Volunteer Rate | J2: CASWJ Board Hours | M2: CASWJ | P2: Start / End Time | R2: Grant Related
A3: Rate Source Year | E3: 2025 | G3: Professional Billing Rate | J3: Committee Member Hours | M3: Literary Arts Society | P3: Total Hours | R3: Board Service
A4: Report Published | E4: 2026 | J4: Participant Hours | M4: Sugar Factory Playhouse | R4: Event Support
A5: Default Rate Type | E5: Utah Volunteer Rate | J5: Volunteer Hours | M5: Visual Arts Society | R5: Administrative
M6: West Jordan Community Band | R6: Community Outreach
M7: West Jordan Jazz Band | R7: Education
M8: West Jordan Symphony | R8: Performance
M9: West Jordan Winds | R9: Production
M10: West Jordan Youth Theatre | R10: Other
A20: Project / Event | B20: Type | C20: Start Date | D20: End Date | E20: Group | F20: Active? | H20: Active Projects / Events
A21: No Specific Project | B21: Project | E21: CASWJ | F21: Yes | H21: =IFERROR(__xludf.DUMMYFUNCTION("FILTER(A21:A1001,F21:F1001=""Yes"")"),"No Specific Project") -> No Specific Project
A22: Literary Arts Society | B22: Project | E22: Literary Arts Society | F22: Yes | H22: =IFERROR(__xludf.DUMMYFUNCTION("""COMPUTED_VALUE"""),"Literary Arts Society") -> Literary Arts Society
A23: Sugar Factory Playhouse | B23: Project | E23: Sugar Factory Playhouse | F23: Yes | H23: =IFERROR(__xludf.DUMMYFUNCTION("""COMPUTED_VALUE"""),"Sugar Factory Playhouse") -> Sugar Factory Playhouse
A24: Visual Arts Society | B24: Project | E24: Visual Arts Society | F24: Yes | H24: =IFERROR(__xludf.DUMMYFUNCTION("""COMPUTED_VALUE"""),"Visual Arts Society") -> Visual Arts Society
A25: West Jordan Community Band | B25: Project | E25: West Jordan Community Band | F25: Yes | H25: =IFERROR(__xludf.DUMMYFUNCTION("""COMPUTED_VALUE"""),"West Jordan Community Band") -> West Jordan Community Band
A26: West Jordan Jazz Band | B26: Project | E26: West Jordan Jazz Band | F26: Yes | H26: =IFERROR(__xludf.DUMMYFUNCTION("""COMPUTED_VALUE"""),"West Jordan Jazz Band") -> West Jordan Jazz Band
A27: West Jordan Symphony | B27: Project | E27: West Jordan Symphony | F27: Yes | H27: =IFERROR(__xludf.DUMMYFUNCTION("""COMPUTED_VALUE"""),"West Jordan Symphony") -> West Jordan Symphony
A28: West Jordan Winds | B28: Project | E28: West Jordan Winds | F28: Yes | H28: =IFERROR(__xludf.DUMMYFUNCTION("""COMPUTED_VALUE"""),"West Jordan Winds") -> West Jordan Winds
A29: West Jordan Youth Theatre | B29: Project | E29: West Jordan Youth Theatre | F29: Yes | H29: =IFERROR(__xludf.DUMMYFUNCTION("""COMPUTED_VALUE"""),"West Jordan Youth Theatre") -> West Jordan Youth Theatre
A30: American Dreams February 2026 | B30: Event | C30: 46060 | E30: Visual Arts Society | F30: Yes | H30: =IFERROR(__xludf.DUMMYFUNCTION("""COMPUTED_VALUE"""),"American Dreams February 2026") -> American Dreams February 2026
A31: Valentine's Concert February 2026 | B31: Event | C31: 46066 | E31: West Jordan Jazz Band | F31: Yes | H31: =IFERROR(__xludf.DUMMYFUNCTION("""COMPUTED_VALUE"""),"Valentine's Concert February 2026") -> Valentine's Concert February 2026
A32: Mid-Winter Concert February 2026 | B32: Event | C32: 46073 | E32: West Jordan Youth Theatre | F32: Yes | H32: =IFERROR(__xludf.DUMMYFUNCTION("""COMPUTED_VALUE"""),"Mid-Winter Concert February 2026") -> Mid-Winter Concert February 2026
A33: Solo & Ensemble Showcase February 2026 | B33: Event | C33: 46081 | E33: West Jordan Symphony | F33: Yes | H33: =IFERROR(__xludf.DUMMYFUNCTION("""COMPUTED_VALUE"""),"Solo & Ensemble Showcase February 2026") -> Solo & Ensemble Showcase February 2026
A34: A Midsummer Night's Dream March 2026 | B34: Event | C34: 46100 | D34: 46109 | E34: Sugar Factory Playhouse | F34: Yes | H34: =IFERROR(__xludf.DUMMYFUNCTION("""COMPUTED_VALUE"""),"A Midsummer Night's Dream March 2026") -> A Midsummer Night's Dream March 2026
A35: Spring Concert April 2026 | B35: Event | C35: 46113 | E35: West Jordan Community Band | F35: Yes | H35: =IFERROR(__xludf.DUMMYFUNCTION("""COMPUTED_VALUE"""),"Spring Concert April 2026") -> Spring Concert April 2026
A36: Spring Concert - April 2026 | B36: Event | C36: 46113 | E36: West Jordan Winds | F36: Yes | H36: =IFERROR(__xludf.DUMMYFUNCTION("""COMPUTED_VALUE"""),"Spring Concert - April 2026") -> Spring Concert - April 2026
A37: Into the Woods - April 2026 | B37: Event | C37: 46129 | D37: 46137 | E37: West Jordan Youth Theatre | F37: Yes | H37: =IFERROR(__xludf.DUMMYFUNCTION("""COMPUTED_VALUE"""),"Into the Woods - April 2026") -> Into the Woods - April 2026
A38: Art in the Park - May 2026 | B38: Event | C38: 46144 | E38: Visual Arts Society | F38: Yes | H38: =IFERROR(__xludf.DUMMYFUNCTION("""COMPUTED_VALUE"""),"Art in the Park - May 2026") -> Art in the Park - May 2026
A39: Summer Concert - May 2026 | B39: Event | C39: 46143 | E39: West Jordan Jazz Band | F39: Yes | H39: =IFERROR(__xludf.DUMMYFUNCTION("""COMPUTED_VALUE"""),"Summer Concert - May 2026") -> Summer Concert - May 2026
A40: Summer Pops Concert - May 2026 | B40: Event | C40: 46171 | E40: West Jordan Community Band | F40: Yes | H40: =IFERROR(__xludf.DUMMYFUNCTION("""COMPUTED_VALUE"""),"Summer Pops Concert - May 2026") -> Summer Pops Concert - May 2026
A41: Generations - A Masterworks Performance - May 2026 | B41: Event | C41: 46172 | E41: West Jordan Symphony | F41: Yes | H41: =IFERROR(__xludf.DUMMYFUNCTION("""COMPUTED_VALUE"""),"Generations - A Masterworks Performance - May 2026") -> Generations - A Masterworks Performance - May 2026
A42: Footloose June 2026 | B42: Event | C42: 46191 | D42: 46200 | E42: Sugar Factory Playhouse | F42: Yes | H42: =IFERROR(__xludf.DUMMYFUNCTION("""COMPUTED_VALUE"""),"Footloose June 2026") -> Footloose June 2026
A43: Mixtape Vol. 1 Road Trip - July 2026 | B43: Event | C43: 46204 | E43: West Jordan Symphony | F43: Yes | H43: =IFERROR(__xludf.DUMMYFUNCTION("""COMPUTED_VALUE"""),"Mixtape Vol. 1 Road Trip - July 2026") -> Mixtape Vol. 1 Road Trip - July 2026
A44: Frozen July & August 2026 | B44: Event | C44: 46234 | D44: 46242 | E44: West Jordan Youth Theatre | F44: Yes | H44: =IFERROR(__xludf.DUMMYFUNCTION("""COMPUTED_VALUE"""),"Frozen July & August 2026") -> Frozen July & August 2026
A45: Hound of the Baskervilles September 2026 | B45: Event | C45: 46282 | D45: 46291 | E45: Sugar Factory Playhouse | F45: Yes | H45: =IFERROR(__xludf.DUMMYFUNCTION("""COMPUTED_VALUE"""),"Hound of the Baskervilles September 2026") -> Hound of the Baskervilles September 2026
A46: Plein Air 2026 | B46: Event | C46: 46291 | E46: Visual Arts Society | F46: Yes | H46: =IFERROR(__xludf.DUMMYFUNCTION("""COMPUTED_VALUE"""),"Plein Air 2026") -> Plein Air 2026
A47: First/Final Concert October 2026 | B47: Event | C47: 46297 | E47: West Jordan Symphony | F47: Yes | H47: =IFERROR(__xludf.DUMMYFUNCTION("""COMPUTED_VALUE"""),"First/Final Concert October 2026") -> First/Final Concert October 2026
A48: Into the Stars October 2026 | B48: Event | C48: 46305 | E48: West Jordan Symphony | F48: Yes | H48: =IFERROR(__xludf.DUMMYFUNCTION("""COMPUTED_VALUE"""),"Into the Stars October 2026") -> Into the Stars October 2026
A49: Fall Concert 2026 | B49: Event | C49: 46310 | E49: West Jordan Community Band | F49: Yes | H49: =IFERROR(__xludf.DUMMYFUNCTION("""COMPUTED_VALUE"""),"Fall Concert 2026") -> Fall Concert 2026
...

Sheet Summary
A1: Total Volunteer Hours | B1: =SUM('Volunteer Log'!J2:J1000) -> 14609.417
A2: Total In-Kind Value | B2: =SUM('Volunteer Log'!M2:M1000) -> 517273.79
A3: Unique Volunteers | B3: =IFERROR(__xludf.DUMMYFUNCTION("COUNTA(UNIQUE(FILTER('Volunteer Log'!C2:C1000,'Volunteer Log'!C2:C1000<>"""")))"),17.0) -> 17
A4: Total Entries | B4: =IFERROR(__xludf.DUMMYFUNCTION("COUNTA(FILTER('Volunteer Log'!A2:A1000,'Volunteer Log'!A2:A1000<>""""))"),249.0) -> 249
A7: Organization | B7: Volunteer Hours | C7: In-Kind Value | E7: Task Category | F7: Volunteer Hours | G7: In-Kind Value | I7: Month | J7: Volunteer Hours | K7: In-Kind Value | M7: Volunteer | N7: Total Hours | O7: In-Kind Value | Q7: Project / Event | R7: Volunteer Hours | S7: In-Kind Value
A8: CASWJ | B8: =SUMIF('Volunteer Log'!D:D,A8,'Volunteer Log'!J:J) -> 89.966667 | C8: =SUMIF('Volunteer Log'!D:D,A8,'Volunteer Log'!M:M) -> 3191.1177 | E8: CASWJ Board Hours | F8: =SUMIF('Volunteer Log'!E:E,E8,'Volunteer Log'!J:J) -> 95.150001 | G8: =SUMIF('Volunteer Log'!E:E,E8,'Volunteer Log'!M:M) -> 3374.9705 | I8: 46023 | J8: =SUMIFS('Volunteer Log'!J:J,'Volunteer Log'!A:A,">="&I8,'Volunteer Log'!A:A,"<"&EDATE(I8,1)) -> 1238.4167 | K8: =SUMIFS('Volunteer Log'!M:M,'Volunteer Log'!A:A,">="&I8,'Volunteer Log'!A:A,"<"&EDATE(I8,1)) -> 43926.639 | M8: =IFERROR(__xludf.DUMMYFUNCTION("QUERY('Volunteer Log'!C2:J1000, ""select C, sum(J) where C is not null and E <> 'Participant Hours' group by C order by sum(J) desc label C '', sum(J) ''"", 0)"),"Anna Nelson") -> Anna Nelson | N8: =IFERROR(__xludf.DUMMYFUNCTION("""COMPUTED_VALUE"""),95.51666899999998) -> 95.516669 | O8: {=IF(M8:M1000="","",SUMIF('Volunteer Log'!C:C,M8:M1000,'Volunteer Log'!M:M))} -> 5010.7287 | Q8: =IFERROR(__xludf.DUMMYFUNCTION("QUERY('Volunteer Log'!B2:J1000, ""select B, sum(J) where B is not null group by B order by sum(J) desc label B '', sum(J) ''"", 0)"),"General - West Jordan Youth Theatre") -> General - West Jordan Youth Theatre | R8: =IFERROR(__xludf.DUMMYFUNCTION("""COMPUTED_VALUE"""),11047.333333) -> 11047.333 | S8: {=IF(Q8:Q1000="","",SUMIF('Volunteer Log'!B:B,Q8:Q1000,'Volunteer Log'!M:M))} -> 391813.44
A9: Literary Arts Society | B9: =SUMIF('Volunteer Log'!D:D,A9,'Volunteer Log'!J:J) -> 0 | C9: =SUMIF('Volunteer Log'!D:D,A9,'Volunteer Log'!M:M) -> 0 | E9: Committee Member Hours | F9: =SUMIF('Volunteer Log'!E:E,E9,'Volunteer Log'!J:J) -> 418.28333 | G9: =SUMIF('Volunteer Log'!E:E,E9,'Volunteer Log'!M:M) -> 13914.29 | I9: 46054 | J9: =SUMIFS('Volunteer Log'!J:J,'Volunteer Log'!A:A,">="&I9,'Volunteer Log'!A:A,"<"&EDATE(I9,1)) -> 1764.3333 | K9: =SUMIFS('Volunteer Log'!M:M,'Volunteer Log'!A:A,">="&I9,'Volunteer Log'!A:A,"<"&EDATE(I9,1)) -> 61694.153 | M9: =IFERROR(__xludf.DUMMYFUNCTION("""COMPUTED_VALUE"""),"Diana Larsen") -> Diana Larsen | N9: =IFERROR(__xludf.DUMMYFUNCTION("""COMPUTED_VALUE"""),92.0) -> 92 | O9: 107202.75 | Q9: =IFERROR(__xludf.DUMMYFUNCTION("""COMPUTED_VALUE"""),"General - West Jordan Symphony") -> General - West Jordan Symphony | R9: =IFERROR(__xludf.DUMMYFUNCTION("""COMPUTED_VALUE"""),3149.316666) -> 3149.3167 | S9: 110819.51
A10: Sugar Factory Playhouse | B10: =SUMIF('Volunteer Log'!D:D,A10,'Volunteer Log'!J:J) -> 33.666666 | C10: =SUMIF('Volunteer Log'!D:D,A10,'Volunteer Log'!M:M) -> 1194.1566 | E10: Participant Hours | F10: =SUMIF('Volunteer Log'!E:E,E10,'Volunteer Log'!J:J) -> 14029.783 | G10: =SUMIF('Volunteer Log'!E:E,E10,'Volunteer Log'!M:M) -> 497636.41 | I10: 46082 | J10: =SUMIFS('Volunteer Log'!J:J,'Volunteer Log'!A:A,">="&I10,'Volunteer Log'!A:A,"<"&EDATE(I10,1)) -> 1912.4 | K10: =SUMIFS('Volunteer Log'!M:M,'Volunteer Log'!A:A,">="&I10,'Volunteer Log'!A:A,"<"&EDATE(I10,1)) -> 67832.828 | M10: =IFERROR(__xludf.DUMMYFUNCTION("""COMPUTED_VALUE"""),"Maya Collinwood") -> Maya Collinwood | N10: =IFERROR(__xludf.DUMMYFUNCTION("""COMPUTED_VALUE"""),71.5) -> 71.5 | O10: 2536.105 | Q10: =IFERROR(__xludf.DUMMYFUNCTION("""COMPUTED_VALUE"""),"General - Visual Arts Society") -> General - Visual Arts Society | R10: =IFERROR(__xludf.DUMMYFUNCTION("""COMPUTED_VALUE"""),210.03333500000002) -> 210.03333 | S10: 7449.8824
A11: Visual Arts Society | B11: =SUMIF('Volunteer Log'!D:D,A11,'Volunteer Log'!J:J) -> 234.95 | C11: =SUMIF('Volunteer Log'!D:D,A11,'Volunteer Log'!M:M) -> 8333.6765 | E11: Volunteer Hours | F11: =SUMIF('Volunteer Log'!E:E,E11,'Volunteer Log'!J:J) -> 66.200001 | G11: =SUMIF('Volunteer Log'!E:E,E11,'Volunteer Log'!M:M) -> 2348.114 | I11: 46113 | J11: =SUMIFS('Volunteer Log'!J:J,'Volunteer Log'!A:A,">="&I11,'Volunteer Log'!A:A,"<"&EDATE(I11,1)) -> 4247.4833 | K11: =SUMIFS('Volunteer Log'!M:M,'Volunteer Log'!A:A,">="&I11,'Volunteer Log'!A:A,"<"&EDATE(I11,1)) -> 150622.76 | M11: =IFERROR(__xludf.DUMMYFUNCTION("""COMPUTED_VALUE"""),"Chelsea McGee") -> Chelsea McGee | N11: =IFERROR(__xludf.DUMMYFUNCTION("""COMPUTED_VALUE"""),60.466667) -> 60.466667 | O11: 2144.7527 | Q11: =IFERROR(__xludf.DUMMYFUNCTION("""COMPUTED_VALUE"""),"General / No Specific Project") -> General / No Specific Project | R11: =IFERROR(__xludf.DUMMYFUNCTION("""COMPUTED_VALUE"""),81.96666700000002) -> 81.966667 | S11: 2907.3577
A12: West Jordan Community Band | B12: =SUMIF('Volunteer Log'!D:D,A12,'Volunteer Log'!J:J) -> 0 | C12: =SUMIF('Volunteer Log'!D:D,A12,'Volunteer Log'!M:M) -> 0 | I12: 46143 | J12: =SUMIFS('Volunteer Log'!J:J,'Volunteer Log'!A:A,">="&I12,'Volunteer Log'!A:A,"<"&EDATE(I12,1)) -> 2218.1833 | K12: =SUMIFS('Volunteer Log'!M:M,'Volunteer Log'!A:A,">="&I12,'Volunteer Log'!A:A,"<"&EDATE(I12,1)) -> 78678.963 | M12: =IFERROR(__xludf.DUMMYFUNCTION("""COMPUTED_VALUE"""),"Samuel Abramson") -> Samuel Abramson | N12: =IFERROR(__xludf.DUMMYFUNCTION("""COMPUTED_VALUE"""),50.0) -> 50 | O12: 1773.5 | Q12: =IFERROR(__xludf.DUMMYFUNCTION("""COMPUTED_VALUE"""),"Plein Air 2026") -> Plein Air 2026 | R12: =IFERROR(__xludf.DUMMYFUNCTION("""COMPUTED_VALUE"""),58.433332) -> 58.433332 | S12: 2072.6303
A13: West Jordan Jazz Band | B13: =SUMIF('Volunteer Log'!D:D,A13,'Volunteer Log'!J:J) -> 0 | C13: =SUMIF('Volunteer Log'!D:D,A13,'Volunteer Log'!M:M) -> 0 | I13: 46174 | J13: =SUMIFS('Volunteer Log'!J:J,'Volunteer Log'!A:A,">="&I13,'Volunteer Log'!A:A,"<"&EDATE(I13,1)) -> 2805.3 | K13: =SUMIFS('Volunteer Log'!M:M,'Volunteer Log'!A:A,">="&I13,'Volunteer Log'!A:A,"<"&EDATE(I13,1)) -> 99503.991 | M13: =IFERROR(__xludf.DUMMYFUNCTION("""COMPUTED_VALUE"""),"Trevor McFarland") -> Trevor McFarland | N13: =IFERROR(__xludf.DUMMYFUNCTION("""COMPUTED_VALUE"""),50.0) -> 50 | O13: 1773.5 | Q13: =IFERROR(__xludf.DUMMYFUNCTION("""COMPUTED_VALUE"""),"General - Sugar Factory Playhouse") -> General - Sugar Factory Playhouse | R13: =IFERROR(__xludf.DUMMYFUNCTION("""COMPUTED_VALUE"""),33.666666) -> 33.666666 | S13: 1194.1566
A14: West Jordan Symphony | B14: =SUMIF('Volunteer Log'!D:D,A14,'Volunteer Log'!J:J) -> 3149.3167 | C14: =SUMIF('Volunteer Log'!D:D,A14,'Volunteer Log'!M:M) -> 110819.51 | I14: 46204 | J14: =SUMIFS('Volunteer Log'!J:J,'Volunteer Log'!A:A,">="&I14,'Volunteer Log'!A:A,"<"&EDATE(I14,1)) -> 32.516667 | K14: =SUMIFS('Volunteer Log'!M:M,'Volunteer Log'!A:A,">="&I14,'Volunteer Log'!A:A,"<"&EDATE(I14,1)) -> 1153.3662 | M14: =IFERROR(__xludf.DUMMYFUNCTION("""COMPUTED_VALUE"""),"Rachel O'Crowley") -> Rachel O'Crowley | N14: =IFERROR(__xludf.DUMMYFUNCTION("""COMPUTED_VALUE"""),47.0) -> 47 | O14: 1667.09 | Q14: =IFERROR(__xludf.DUMMYFUNCTION("""COMPUTED_VALUE"""),"Art in the Park May 2026") -> Art in the Park May 2026 | R14: =IFERROR(__xludf.DUMMYFUNCTION("""COMPUTED_VALUE"""),10.25) -> 10.25 | S14: 363.5675
A15: West Jordan Winds | B15: =SUMIF('Volunteer Log'!D:D,A15,'Volunteer Log'!J:J) -> 0 | C15: =SUMIF('Volunteer Log'!D:D,A15,'Volunteer Log'!M:M) -> 0 | I15: 46235 | J15: =SUMIFS('Volunteer Log'!J:J,'Volunteer Log'!A:A,">="&I15,'Volunteer Log'!A:A,"<"&EDATE(I15,1)) -> 288.05 | K15: =SUMIFS('Volunteer Log'!M:M,'Volunteer Log'!A:A,">="&I15,'Volunteer Log'!A:A,"<"&EDATE(I15,1)) -> 10217.134 | M15: =IFERROR(__xludf.DUMMYFUNCTION("""COMPUTED_VALUE"""),"Jen Crabb") -> Jen Crabb | N15: =IFERROR(__xludf.DUMMYFUNCTION("""COMPUTED_VALUE"""),42.666666) -> 42.666666 | O15: 1513.3866 | Q15: =IFERROR(__xludf.DUMMYFUNCTION("""COMPUTED_VALUE"""),"General - Literary Arts Society") -> General - Literary Arts Society | R15: =IFERROR(__xludf.DUMMYFUNCTION("""COMPUTED_VALUE"""),8.166667) -> 8.166667 | S15: 289.67168
A16: West Jordan Youth Theatre | B16: =SUMIF('Volunteer Log'!D:D,A16,'Volunteer Log'!J:J) -> 11047.333 | C16: =SUMIF('Volunteer Log'!D:D,A16,'Volunteer Log'!M:M) -> 391813.44 | I16: 46266 | J16: =SUMIFS('Volunteer Log'!J:J,'Volunteer Log'!A:A,">="&I16,'Volunteer Log'!A:A,"<"&EDATE(I16,1)) -> 102.51667 | K16: =SUMIFS('Volunteer Log'!M:M,'Volunteer Log'!A:A,">="&I16,'Volunteer Log'!A:A,"<"&EDATE(I16,1)) -> 3636.2661 | M16: =IFERROR(__xludf.DUMMYFUNCTION("""COMPUTED_VALUE"""),"Briana Thaxton") -> Briana Thaxton | N16: =IFERROR(__xludf.DUMMYFUNCTION("""COMPUTED_VALUE"""),29.499999000000003) -> 29.499999 | O16: 1046.365 | Q16: =IFERROR(__xludf.DUMMYFUNCTION("""COMPUTED_VALUE"""),"Art in the Park 2026") -> Art in the Park 2026 | R16: =IFERROR(__xludf.DUMMYFUNCTION("""COMPUTED_VALUE"""),5.066666) -> 5.066666 | S16: 179.71464
I17: 46296 | J17: =SUMIFS('Volunteer Log'!J:J,'Volunteer Log'!A:A,">="&I17,'Volunteer Log'!A:A,"<"&EDATE(I17,1)) -> 0.216667 | K17: =SUMIFS('Volunteer Log'!M:M,'Volunteer Log'!A:A,">="&I17,'Volunteer Log'!A:A,"<"&EDATE(I17,1)) -> 7.6851785 | M17: =IFERROR(__xludf.DUMMYFUNCTION("""COMPUTED_VALUE"""),"Lynette Owens") -> Lynette Owens | N17: =IFERROR(__xludf.DUMMYFUNCTION("""COMPUTED_VALUE"""),6.683334) -> 6.683334 | O17: 237.05786
I18: 46327 | J18: =SUMIFS('Volunteer Log'!J:J,'Volunteer Log'!A:A,">="&I18,'Volunteer Log'!A:A,"<"&EDATE(I18,1)) -> 0 | K18: =SUMIFS('Volunteer Log'!M:M,'Volunteer Log'!A:A,">="&I18,'Volunteer Log'!A:A,"<"&EDATE(I18,1)) -> 0 | M18: =IFERROR(__xludf.DUMMYFUNCTION("""COMPUTED_VALUE"""),"Michael Goodman") -> Michael Goodman | N18: =IFERROR(__xludf.DUMMYFUNCTION("""COMPUTED_VALUE"""),4.0) -> 4 | O18: 141.88
I19: 46357 | J19: =SUMIFS('Volunteer Log'!J:J,'Volunteer Log'!A:A,">="&I19,'Volunteer Log'!A:A,"<"&EDATE(I19,1)) -> 0 | K19: =SUMIFS('Volunteer Log'!M:M,'Volunteer Log'!A:A,">="&I19,'Volunteer Log'!A:A,"<"&EDATE(I19,1)) -> 0 | M19: =IFERROR(__xludf.DUMMYFUNCTION("""COMPUTED_VALUE"""),"Brook Mann") -> Brook Mann | N19: =IFERROR(__xludf.DUMMYFUNCTION("""COMPUTED_VALUE"""),1.333333) -> 1.333333 | O19: 47.293322
M20: =IFERROR(__xludf.DUMMYFUNCTION("""COMPUTED_VALUE"""),"Kirstin Hoyt") -> Kirstin Hoyt | N20: =IFERROR(__xludf.DUMMYFUNCTION("""COMPUTED_VALUE"""),1.25) -> 1.25 | O20: 44.3375
M21: =IFERROR(__xludf.DUMMYFUNCTION("""COMPUTED_VALUE"""),"Becca Henrie") -> Becca Henrie | N21: =IFERROR(__xludf.DUMMYFUNCTION("""COMPUTED_VALUE"""),1.0) -> 1 | O21: 0
M22: =IFERROR(__xludf.DUMMYFUNCTION("""COMPUTED_VALUE"""),"Janessa Kimball") -> Janessa Kimball | N22: =IFERROR(__xludf.DUMMYFUNCTION("""COMPUTED_VALUE"""),1.0) -> 1 | O22: 35.47
M23: =IFERROR(__xludf.DUMMYFUNCTION("""COMPUTED_VALUE"""),"Marche Weffer") -> Marche Weffer | N23: =IFERROR(__xludf.DUMMYFUNCTION("""COMPUTED_VALUE"""),0.7166669999999999) -> 0.716667 | O23: 25.420178

Sheet Clockify Import
A1: Project | B1: Client | C1: Description | D1: Task | E1: User | F1: Group | G1: Email | H1: Tags | I1: Billable | J1: Start Date | K1: Start Time | L1: End Date | M1: End Time | N1: Duration (h) | O1: Duration (decimal) | P1: Billable Rate (USD) | Q1: Billable Amount (USD) | R1: Date of creation | S1: Clean Date | T1: Clean Project / Event | U1: Clean Volunteer | V1: Clean Group / Organization | W1: Clean Task Category | X1: Clean Entry Method | Y1: Clean Manual Hours | Z1: Clean Tags | AA1: Clean Entered By | AB1: Clean Date Entered | AC1: Clean Notes | AD1: Clockify User | AE1: Clockify Email | AF1: Volunteer Display Name | AH1: Clockify Group | AI1: Clean Group / Organization | AK1: Clockify Description | AN1: Default Group / Organization | AO1: Clockify Tag | AP1: Date | AQ1: Project / Event | AR1: Volunteer | AS1: Group / Organization | AT1: Task Category | AU1: Entry Method | AV1: Start Time | AW1: End Time | AX1: Manual Hours | AY1: Hours | AZ1: Rate Type | BA1: Hourly Rate | BB1: In-Kind Value | BC1: Tags | BD1: Entered By | BE1: Date Entered | BF1: Notes
A2: 2026 Volunteer Hours | C2: Trevor McFarland - Director/January | E2: diana | F2: West Jordan Symphony | H2: (Org) West Jordan Symphony, (Type) Committee Member Hours | J2: 46053 | K2: 0.875 | L2: 46054 | M2: 0.91666667 | N2: 1.0416667 | O2: 25 | S2: {=IF(J2:J238="","",J2:J238)} -> 46053 | T2: =IFERROR(__xludf.DUMMYFUNCTION("ARRAYFORMULA( IF(E2:E238="""","""", IFNA( TRIM(REGEXEXTRACT(H2:H238,""\(Event\)\s*([^,]+)"")), IF( V2:V238="""", """", IF(V2:V238=""CASWJ"",""General / No Specific Project"",""General - ""&V2:V238) ) )))"),"General - West Jordan Symphony") -> General - West Jordan Symphony | U2: {=IF(E2:E238="","", TRIM(CLEAN(IFNA(VLOOKUP(E2:E238,$AD$2:$AF1000,3,FALSE),""))) )} -> Diana Larsen | V2: {=IF(E2:E238="","", IF( F2:F238<>"", IFNA(VLOOKUP(F2:F238,$AH$2:$AI1000,2,FALSE),""), SWITCH( E2:E238, "Anna Nelson","Visual Arts Society", "becca.henrie","West Jordan Youth Theatre", "Jen.crabb","Sugar Factory Playhouse", "jkimball","CASWJ", "Marche","West Jordan Symphony", "" ) ))} -> West Jordan Symphony | W2: =IFERROR(__xludf.DUMMYFUNCTION("ARRAYFORMULA( IF(H2:H238="""","""", IFNA(TRIM(REGEXEXTRACT(H2:H238,""\(Type\)\s*([^,]+)"")),"""") ))"),"Committee Member Hours") -> Committee Member Hours | X2: {=IF(S2:S238="","","Total Hours")} -> Total Hours | Y2: {=IF(O2:O238="","",O2:O238)} -> 25 | Z2: {=IF(H2:H238="","",H2:H238)} -> (Org) West Jordan Symphony, (Type) Committee Member Hours | AA2: {=IF(S2:S238="","","Clockify Import")} -> Clockify Import | AB2: {=IF(S2:S238="","",S2:S238)} -> 46053 | AC2: {=IF(C2:C238="","",C2:C238)} -> Trevor McFarland - Director/January | AD2: =IFERROR(__xludf.DUMMYFUNCTION("UNIQUE(FILTER({E2:E1000,G2:G1000},E2:E1000<>""""))"),"diana") -> diana | AF2: Diana Larsen | AH2: West Jordan Symphony | AI2: West Jordan Symphony | AK2: =IFERROR(__xludf.DUMMYFUNCTION("SORT(UNIQUE(FILTER(C2:C1000,C2:C1000<>"""")))"),"(Without Description)") -> (Without Description) | AO2: =IFERROR(__xludf.DUMMYFUNCTION("SORT(UNIQUE(TRIM(TOCOL(SPLIT(TEXTJOIN("","",TRUE,FILTER(H2:H1000,H2:H1000<>"""")),"",""),1))))"),"(Event) Art in the Park 2026") -> (Event) Art in the Park 2026 | AP2: {={ S2:S238, T2:T238, U2:U238, V2:V238, W2:W238, X2:X238, K2:K238, M2:M238, Y2:Y238, IF(S2:S238<>"","",""), IF(S2:S238<>"","",""), IF(S2:S238<>"","",""), IF(S2:S238<>"","",""), Z2:Z238, AA2:AA238, AB2:AB238, AC2:AC238 }} -> 46053 | AQ2: General - West Jordan Symphony | AR2: Diana Larsen | AS2: West Jordan Symphony | AT2: Committee Member Hours | AU2: Total Hours | AV2: 0.875 | AW2: 0.91666667 | AX2: 25 | BC2: (Org) West Jordan Symphony, (Type) Committee Member Hours | BD2: Clockify Import | BE2: 46053 | BF2: Trevor McFarland - Director/January
A3: 2026 Volunteer Hours | C3: Sam Abramson- Assistant Director/January | E3: diana | F3: West Jordan Symphony | H3: (Org) West Jordan Symphony, (Type) Committee Member Hours | J3: 46053 | K3: 0.875 | L3: 46054 | M3: 0.91666667 | N3: 1.0416667 | O3: 25 | S3: 46053 | T3: =IFERROR(__xludf.DUMMYFUNCTION("""COMPUTED_VALUE"""),"General - West Jordan Symphony") -> General - West Jordan Symphony | U3: Diana Larsen | V3: West Jordan Symphony | W3: =IFERROR(__xludf.DUMMYFUNCTION("""COMPUTED_VALUE"""),"Committee Member Hours") -> Committee Member Hours | X3: Total Hours | Y3: 25 | Z3: (Org) West Jordan Symphony, (Type) Committee Member Hours | AA3: Clockify Import | AB3: 46053 | AC3: Sam Abramson- Assistant Director/January | AD3: =IFERROR(__xludf.DUMMYFUNCTION("""COMPUTED_VALUE"""),"Alex.moffitt") -> Alex.moffitt | AF3: Alex Moffitt | AH3: West Jordan Youth Theatre | AI3: West Jordan Youth Theatre | AK3: =IFERROR(__xludf.DUMMYFUNCTION("""COMPUTED_VALUE"""),"Art in the park") -> Art in the park | AO3: =IFERROR(__xludf.DUMMYFUNCTION("""COMPUTED_VALUE"""),"(Org) CASWJ Board") -> (Org) CASWJ Board | AP3: 46053 | AQ3: General - West Jordan Symphony | AR3: Diana Larsen | AS3: West Jordan Symphony | AT3: Committee Member Hours | AU3: Total Hours | AV3: 0.875 | AW3: 0.91666667 | AX3: 25 | BC3: (Org) West Jordan Symphony, (Type) Committee Member Hours | BD3: Clockify Import | BE3: 46053 | BF3: Sam Abramson- Assistant Director/January
A4: 2026 Volunteer Hours | C4: WJYT January Volunteer Hours | E4: Alex.moffitt | F4: West Jordan Youth Theatre | H4: (Org) West Jordan Youth Theatre | J4: 46053 | K4: 0.75902778 | L4: 46084 | M4: 0.17569444 | N4: 30.416667 | O4: 730 | S4: 46053 | T4: =IFERROR(__xludf.DUMMYFUNCTION("""COMPUTED_VALUE"""),"General - West Jordan Youth Theatre") -> General - West Jordan Youth Theatre | U4: Alex Moffitt | V4: West Jordan Youth Theatre | W4: =IFERROR(__xludf.DUMMYFUNCTION("""COMPUTED_VALUE"""),"") | X4: Total Hours | Y4: 730 | Z4: (Org) West Jordan Youth Theatre | AA4: Clockify Import | AB4: 46053 | AC4: WJYT January Volunteer Hours | AD4: =IFERROR(__xludf.DUMMYFUNCTION("""COMPUTED_VALUE"""),"brianna.thaxton") -> brianna.thaxton | AF4: Briana Thaxton | AH4: Visual Arts Society | AI4: Visual Arts Society | AK4: =IFERROR(__xludf.DUMMYFUNCTION("""COMPUTED_VALUE"""),"Art in the Park") -> Art in the Park | AO4: =IFERROR(__xludf.DUMMYFUNCTION("""COMPUTED_VALUE"""),"(Org) Sugar Factory Playhouse") -> (Org) Sugar Factory Playhouse | AP4: 46053 | AQ4: General - West Jordan Youth Theatre | AR4: Alex Moffitt | AS4: West Jordan Youth Theatre | AU4: Total Hours | AV4: 0.75902778 | AW4: 0.17569444 | AX4: 730 | BC4: (Org) West Jordan Youth Theatre | BD4: Clockify Import | BE4: 46053 | BF4: WJYT January Volunteer Hours
A5: 2026 Volunteer Hours | C5: Board members/January | E5: diana | F5: West Jordan Symphony | H5: (Org) West Jordan Symphony, (Type) Committee Member Hours | J5: 46053 | K5: 0.375 | L5: 46054 | M5: 0.41666667 | N5: 1.0416667 | O5: 25 | S5: 46053 | T5: =IFERROR(__xludf.DUMMYFUNCTION("""COMPUTED_VALUE"""),"General - West Jordan Symphony") -> General - West Jordan Symphony | U5: Diana Larsen | V5: West Jordan Symphony | W5: =IFERROR(__xludf.DUMMYFUNCTION("""COMPUTED_VALUE"""),"Committee Member Hours") -> Committee Member Hours | X5: Total Hours | Y5: 25 | Z5: (Org) West Jordan Symphony, (Type) Committee Member Hours | AA5: Clockify Import | AB5: 46053 | AC5: Board members/January | AD5: =IFERROR(__xludf.DUMMYFUNCTION("""COMPUTED_VALUE"""),"Anna Nelson") -> Anna Nelson | AF5: Anna Nelson | AH5: CASWJ Board | AI5: CASWJ | AK5: =IFERROR(__xludf.DUMMYFUNCTION("""COMPUTED_VALUE"""),"Art in the Park SFP") -> Art in the Park SFP | AO5: =IFERROR(__xludf.DUMMYFUNCTION("""COMPUTED_VALUE"""),"(Org) Visual Arts Society") -> (Org) Visual Arts Society | AP5: 46053 | AQ5: General - West Jordan Symphony | AR5: Diana Larsen | AS5: West Jordan Symphony | AT5: Committee Member Hours | AU5: Total Hours | AV5: 0.375 | AW5: 0.41666667 | AX5: 25 | BC5: (Org) West Jordan Symphony, (Type) Committee Member Hours | BD5: Clockify Import | BE5: 46053 | BF5: Board members/January
A6: 2026 Volunteer Hours | C6: Rehearsal | E6: diana | F6: West Jordan Symphony | H6: (Type) Participant Hours, (Org) West Jordan Symphony | J6: 46053 | K6: 0.375 | L6: 46057 | M6: 0.85416667 | N6: 4.4791667 | O6: 107.5 | S6: 46053 | T6: =IFERROR(__xludf.DUMMYFUNCTION("""COMPUTED_VALUE"""),"General - West Jordan Symphony") -> General - West Jordan Symphony | U6: Diana Larsen | V6: West Jordan Symphony | W6: =IFERROR(__xludf.DUMMYFUNCTION("""COMPUTED_VALUE"""),"Participant Hours") -> Participant Hours | X6: Total Hours | Y6: 107.5 | Z6: (Type) Participant Hours, (Org) West Jordan Symphony | AA6: Clockify Import | AB6: 46053 | AC6: Rehearsal | AD6: =IFERROR(__xludf.DUMMYFUNCTION("""COMPUTED_VALUE"""),"maya.collinwood") -> maya.collinwood | AF6: Maya Collinwood | AH6: Sugar Factory Playhouse | AI6: Sugar Factory Playhouse | AK6: =IFERROR(__xludf.DUMMYFUNCTION("""COMPUTED_VALUE"""),"Art in the Park Volunteer") -> Art in the Park Volunteer | AO6: =IFERROR(__xludf.DUMMYFUNCTION("""COMPUTED_VALUE"""),"(Org) West Jordan Symphony") -> (Org) West Jordan Symphony | AP6: 46053 | AQ6: General - West Jordan Symphony | AR6: Diana Larsen | AS6: West Jordan Symphony | AT6: Participant Hours | AU6: Total Hours | AV6: 0.375 | AW6: 0.85416667 | AX6: 107.5 | BC6: (Type) Participant Hours, (Org) West Jordan Symphony | BD6: Clockify Import | BE6: 46053 | BF6: Rehearsal
A7: 2026 Volunteer Hours | C7: Google Meet with Dillon | E7: brianna.thaxton | F7: Visual Arts Society | H7: (Event) Art in the Park 2026, (Org) Visual Arts Society, (Type) Committee Member Hours | J7: 46050 | K7: 0.54166667 | L7: 46050 | M7: 0.58680556 | N7: 0.045138889 | O7: 1.083333 | S7: 46050 | T7: =IFERROR(__xludf.DUMMYFUNCTION("""COMPUTED_VALUE"""),"Art in the Park 2026") -> Art in the Park 2026 | U7: Briana Thaxton | V7: Visual Arts Society | W7: =IFERROR(__xludf.DUMMYFUNCTION("""COMPUTED_VALUE"""),"Committee Member Hours") -> Committee Member Hours | X7: Total Hours | Y7: 1.083333 | Z7: (Event) Art in the Park 2026, (Org) Visual Arts Society, (Type) Committee Member Hours | AA7: Clockify Import | AB7: 46050 | AC7: Google Meet with Dillon | AD7: =IFERROR(__xludf.DUMMYFUNCTION("""COMPUTED_VALUE"""),"rocrowley") -> rocrowley | AF7: Rachel O'Crowley | AK7: =IFERROR(__xludf.DUMMYFUNCTION("""COMPUTED_VALUE"""),"Art in the park volunteer form and flyer") -> Art in the park volunteer form and flyer | AO7: =IFERROR(__xludf.DUMMYFUNCTION("""COMPUTED_VALUE"""),"(Org) West Jordan Youth Theatre") -> (Org) West Jordan Youth Theatre | AP7: 46050 | AQ7: Art in the Park 2026 | AR7: Briana Thaxton | AS7: Visual Arts Society | AT7: Committee Member Hours | AU7: Total Hours | AV7: 0.54166667 | AW7: 0.58680556 | AX7: 1.083333 | BC7: (Event) Art in the Park 2026, (Org) Visual Arts Society, (Type) Committee Member Hours | BD7: Clockify Import | BE7: 46050 | BF7: Google Meet with Dillon
A8: 2026 Volunteer Hours | C8: Rehearsal | E8: diana | F8: West Jordan Symphony | H8: (Type) Participant Hours, (Org) West Jordan Symphony | J8: 46046 | K8: 0.375 | L8: 46051 | M8: 0.375 | N8: 5 | O8: 120 | S8: 46046 | T8: =IFERROR(__xludf.DUMMYFUNCTION("""COMPUTED_VALUE"""),"General - West Jordan Symphony") -> General - West Jordan Symphony | U8: Diana Larsen | V8: West Jordan Symphony | W8: =IFERROR(__xludf.DUMMYFUNCTION("""COMPUTED_VALUE"""),"Participant Hours") -> Participant Hours | X8: Total Hours | Y8: 120 | Z8: (Type) Participant Hours, (Org) West Jordan Symphony | AA8: Clockify Import | AB8: 46046 | AC8: Rehearsal | AD8: =IFERROR(__xludf.DUMMYFUNCTION("""COMPUTED_VALUE"""),"lynnette111owens") -> lynnette111owens | AF8: Lynette Owens | AK8: =IFERROR(__xludf.DUMMYFUNCTION("""COMPUTED_VALUE"""),"Artist Apps") -> Artist Apps | AO8: =IFERROR(__xludf.DUMMYFUNCTION("""COMPUTED_VALUE"""),"(Type) CASWJ Board Hours") -> (Type) CASWJ Board Hours | AP8: 46046 | AQ8: General - West Jordan Symphony | AR8: Diana Larsen | AS8: West Jordan Symphony | AT8: Participant Hours | AU8: Total Hours | AV8: 0.375 | AW8: 0.375 | AX8: 120 | BC8: (Type) Participant Hours, (Org) West Jordan Symphony | BD8: Clockify Import | BE8: 46046 | BF8: Rehearsal
